<?xml version="1.0" encoding="utf-8"?>
<!-- This URDF was automatically created by SolidWorks to URDF Exporter! Originally created by Stephen Brawner (brawner@gmail.com) 
     Commit Version: 1.6.0-4-g7f85cfe  Build Version: 1.6.7995.38578
     For more information, please see http://wiki.ros.org/sw_urdf_exporter -->
<robot
  name="arm_dm_description">
  <link
    name="base_link">
    <inertial>
      <origin
        xyz="-1.4614E-05 2.7564E-09 0.019963"
        rpy="0 0 0" />
      <mass
        value="0.976" />
      <inertia
        ixx="0.00089488"
        ixy="1.1047E-08"
        ixz="1.14E-08"
        iyy="0.00089762"
        iyz="-1.9084E-12"
        izz="0.0016544" />
    </inertial>
    <visual>
      <origin
        xyz="0 0 0"
        rpy="0 0 0" />
      <geometry>
        <mesh
          filename="package://arm_dm_description/meshes/base_link.STL" />
      </geometry>
      <material
        name="">
        <color
          rgba="0.89804 0.91765 0.92941 1" />
      </material>
    </visual>
    <collision>
      <origin
        xyz="0 0 0"
        rpy="0 0 0" />
      <geometry>
        <mesh
          filename="package://arm_dm_description/meshes/base_link.STL" />
      </geometry>
    </collision>
  </link>
  <link
    name="link1">
    <inertial>
      <origin
        xyz="0.0027728 2.1768E-14 0.017932"
        rpy="0 0 0" />
      <mass
        value="0.138" />
      <inertia
        ixx="4.9774E-05"
        ixy="3.7599E-19"
        ixz="4.964E-07"
        iyy="3.9409E-05"
        iyz="-1.4791E-17"
        izz="4.9343E-05" />
    </inertial>
    <visual>
      <origin
        xyz="0 0 0"
        rpy="0 0 0" />
      <geometry>
        <mesh
          filename="package://arm_dm_description/meshes/link1.STL" />
      </geometry>
      <material
        name="">
        <color
          rgba="0.89804 0.91765 0.92941 1" />
      </material>
    </visual>
    <collision>
      <origin
        xyz="0 0 0"
        rpy="0 0 0" />
      <geometry>
        <mesh
          filename="package://arm_dm_description/meshes/link1.STL" />
      </geometry>
    </collision>
  </link>
  <joint
    name="joint1"
    type="revolute">
    <origin
      xyz="0 0 0.06475"
      rpy="0 0 0" />
    <parent
      link="base_link" />
    <child
      link="link1" />
    <axis
      xyz="0 0 1" />
    <limit
      lower="-1.57"
      upper="1.57"
      effort="26"
      velocity="30" />
  </joint>
  <link
    name="link2">
    <inertial>
      <origin
        xyz="-0.0035914 -0.14996 9.5822E-09"
        rpy="0 0 0" />
      <mass
        value="1.379" />
      <inertia
        ixx="0.0043271"
        ixy="-6.9375E-08"
        ixz="-2.086E-10"
        iyy="0.00024179"
        iyz="-2.1753E-08"
        izz="0.0043582" />
    </inertial>
    <visual>
      <origin
        xyz="0 0 0"
        rpy="0 0 0" />
      <geometry>
        <mesh
          filename="package://arm_dm_description/meshes/link2.STL" />
      </geometry>
      <material
        name="">
        <color
          rgba="0.22353 0.22353 0.22353 1" />
      </material>
    </visual>
    <collision>
      <origin
        xyz="0 0 0"
        rpy="0 0 0" />
      <geometry>
        <mesh
          filename="package://arm_dm_description/meshes/link2.STL" />
      </geometry>
    </collision>
  </link>
  <joint
    name="joint2"
    type="revolute">
    <origin
      xyz="0.00325 0 0.04575"
      rpy="0 0 0" />
    <parent
      link="link1" />
    <child
      link="link2" />
    <axis
      xyz="1 0 0" />
    <limit
      lower="-3.14"
      upper="0"
      effort="26"
      velocity="30" />
  </joint>
  <link
    name="link3">
    <inertial>
      <origin
        xyz="-0.00257 0.09923 0.051397"
        rpy="0 0 0" />
      <mass
        value="0.727" />
      <inertia
        ixx="0.0011822"
        ixy="-2.0778E-06"
        ixz="-1.411E-06"
        iyy="0.0003301"
        iyz="-0.00031014"
        izz="0.00096288" />
    </inertial>
    <visual>
      <origin
        xyz="0 0 0"
        rpy="0 0 0" />
      <geometry>
        <mesh
          filename="package://arm_dm_description/meshes/link3.STL" />
      </geometry>
      <material
        name="">
        <color
          rgba="0.89804 0.91765 0.92941 1" />
      </material>
    </visual>
    <collision>
      <origin
        xyz="0 0 0"
        rpy="0 0 0" />
      <geometry>
        <mesh
          filename="package://arm_dm_description/meshes/link3.STL" />
      </geometry>
    </collision>
  </link>
  <joint
    name="joint3"
    type="revolute">
    <origin
      xyz="0 -0.3 0"
      rpy="0 0 0" />
    <parent
      link="link2" />
    <child
      link="link3" />
    <axis
      xyz="1 0 0" />
    <limit
      lower="0"
      upper="2"
      effort="26"
      velocity="30" />
  </joint>
  <link
    name="link4">
    <inertial>
      <origin
        xyz="0.0034984 0.028153 -1.0623E-06"
        rpy="0 0 0" />
      <mass
        value="0.370" />
      <inertia
        ixx="6.9729E-05"
        ixy="3.8219E-09"
        ixz="-1.909E-12"
        iyy="5.8234E-05"
        iyz="-2.1963E-08"
        izz="5.0848E-05" />
    </inertial>
    <visual>
      <origin
        xyz="0 0 0"
        rpy="0 0 0" />
      <geometry>
        <mesh
          filename="package://arm_dm_description/meshes/link4.STL" />
      </geometry>
      <material
        name="">
        <color
          rgba="0.89804 0.91765 0.92941 1" />
      </material>
    </visual>
    <collision>
      <origin
        xyz="0 0 0"
        rpy="0 0 0" />
      <geometry>
        <mesh
          filename="package://arm_dm_description/meshes/link4.STL" />
      </geometry>
    </collision>
  </link>
  <joint
    name="joint4"
    type="revolute">
    <origin
      xyz="-0.00325 0.218 0.065"
      rpy="0 0 0" />
    <parent
      link="link3" />
    <child
      link="link4" />
    <axis
      xyz="0 -1 0" />
    <limit
      lower="-3"
      upper="3"
      effort="26"
      velocity="30" />
  </joint>
  <link
    name="link5">
    <inertial>
      <origin
        xyz="-0.00068876 0.076386 -1.3572E-05"
        rpy="0 0 0" />
      <mass
        value="0.391" />
      <inertia
        ixx="0.00011865"
        ixy="-9.3104E-08"
        ixz="2.9613E-06"
        iyy="0.00021653"
        iyz="1.1425E-08"
        izz="0.00020595" />
    </inertial>
    <visual>
      <origin
        xyz="0 0 0"
        rpy="0 0 0" />
      <geometry>
        <mesh
          filename="package://arm_dm_description/meshes/link5.STL" />
      </geometry>
      <material
        name="">
        <color
          rgba="0.89804 0.91765 0.92941 1" />
      </material>
    </visual>
    <collision>
      <origin
        xyz="0 0 0"
        rpy="0 0 0" />
      <geometry>
        <mesh
          filename="package://arm_dm_description/meshes/link5.STL" />
      </geometry>
    </collision>
  </link>
  <joint
    name="joint5"
    type="revolute">
    <origin
      xyz="-0.00275 0.036 0"
      rpy="0 0 0" />
    <parent
      link="link4" />
    <child
      link="link5" />
    <axis
      xyz="1 0 0" />
    <limit
      lower="-1.28"
      upper="1.28"
      effort="26"
      velocity="30" />
  </joint>
  <link
    name="link6">
    <inertial>
      <origin
        xyz="1.8842E-15 0.0065 -1.5543E-15"
        rpy="0 0 0" />
      <mass
        value="0.179" />
      <inertia
        ixx="3.5845E-07"
        ixy="-4.139E-22"
        ixz="1.9791E-23"
        iyy="6.9773E-07"
        iyz="-1.448E-21"
        izz="3.5845E-07" />
    </inertial>
    <visual>
      <origin
        xyz="0 0 0"
        rpy="0 0 0" />
      <geometry>
        <mesh
          filename="package://arm_dm_description/meshes/link6.STL" />
      </geometry>
      <material
        name="">
        <color
          rgba="1 0.24706 0.24706 1" />
      </material>
    </visual>
    <collision>
      <origin
        xyz="0 0 0"
        rpy="0 0 0" />
      <geometry>
        <mesh
          filename="package://arm_dm_description/meshes/link6.STL" />
      </geometry>
    </collision>
  </link>
  <joint
    name="joint6"
    type="revolute">
    <origin
      xyz="0.00275 0.082 0"
      rpy="0 0 0" />
    <parent
      link="link5" />
    <child
      link="link6" />
    <axis
      xyz="0 -1 0" />
    <limit
      lower="0"
      upper="1.1"
      effort="26"
      velocity="30" />
  </joint>
  <!-- 在末端法兰后添加TCP 2025.12.14-->
  <link name="tcp_link">
    <visual>
      <geometry>
        <sphere radius="0.01"/>  <!-- 可视化标记 -->
      </geometry>
      <material name="red">
        <color rgba="1 0 0 1"/>
      </material>
    </visual>
  </link>

  <joint name="tool_flange_to_tcp" type="fixed">
    <parent link="link6"/>  <!-- 你的末端link名称,可能是tool0或Link6 -->
    <child link="tcp_link"/>
    <!-- 根据你的实际工具长度设置偏移,例如夹爪中心点 -->
    <origin xyz="0.0 0.09 0.0" rpy="0 0 0"/>  
  </joint>

</robot>